<?xml version="1.0" encoding="utf-8"?>
<!-- This URDF was automatically created by SolidWorks to URDF Exporter! Originally created by Stephen Brawner (brawner@gmail.com) 
     Commit Version: 1.6.0-4-g7f85cfe  Build Version: 1.6.7995.38578
     For more information, please see http://wiki.ros.org/sw_urdf_exporter -->
<robot
  name="Run_URDF">
  <link
    name="base_link">
    <inertial>
      <origin
        xyz="1.9086E-18 -3.7577E-18 0.57199"
        rpy="0 0 0" />
      <mass
        value="39.222" />
      <inertia
        ixx="1.0521"
        ixy="-2.0159E-18"
        ixz="-3.0345E-18"
        iyy="1.0016"
        iyz="-4.5953E-17"
        izz="0.1045" />
    </inertial>
    <visual>
      <origin
        xyz="0 0 0"
        rpy="0 0 0" />
      <geometry>
        <mesh
          filename="package://Run_URDF/meshes/base_link.STL" />
      </geometry>
      <material
        name="">
        <color
          rgba="0.64706 0.61961 0.58824 1" />
      </material>
    </visual>
    <collision>
      <origin
        xyz="0 0 0"
        rpy="0 0 0" />
      <geometry>
        <mesh
          filename="package://Run_URDF/meshes/base_link.STL" />
      </geometry>
    </collision>
  </link>
  <link
    name="shoulder_pitch_r">
    <inertial>
      <origin
        xyz="4.3591E-19 2.7756E-17 -0.14232"
        rpy="0 0 0" />
      <mass
        value="6.3152" />
      <inertia
        ixx="0.055898"
        ixy="3.3087E-21"
        ixz="7.6066E-19"
        iyy="0.05583"
        iyz="9.4966E-19"
        izz="0.0026781" />
    </inertial>
    <visual>
      <origin
        xyz="0 0 0"
        rpy="0 0 0" />
      <geometry>
        <mesh
          filename="package://Run_URDF/meshes/shoulder_pitch_r.STL" />
      </geometry>
      <material
        name="">
        <color
          rgba="0.64706 0.61961 0.58824 1" />
      </material>
    </visual>
    <collision>
      <origin
        xyz="0 0 0"
        rpy="0 0 0" />
      <geometry>
        <mesh
          filename="package://Run_URDF/meshes/shoulder_pitch_r.STL" />
      </geometry>
    </collision>
  </link>
  <joint
    name="shoulder_pitch_r"
    type="revolute">
    <origin
      xyz="0 -0.175 0.6"
      rpy="0 0 0" />
    <parent
      link="base_link" />
    <child
      link="shoulder-pitch-r" />
    <axis
      xyz="0 -1 0" />
    <limit
      lower="-1.57"
      upper="1.57"
      effort="57.2"
      velocity="15.71" />
  </joint>
  <link
    name="elbow_pitch_r">
    <inertial>
      <origin
        xyz="-2.3729E-18 0 -0.16991"
        rpy="0 0 0" />
      <mass
        value="5.3737" />
      <inertia
        ixx="0.054667"
        ixy="-8.2201E-21"
        ixz="8.424E-20"
        iyy="0.054709"
        iyz="3.7839E-20"
        izz="0.0016306" />
    </inertial>
    <visual>
      <origin
        xyz="0 0 0"
        rpy="0 0 0" />
      <geometry>
        <mesh
          filename="package://Run_URDF/meshes/elbow_pitch_r.STL" />
      </geometry>
      <material
        name="">
        <color
          rgba="0.64706 0.61961 0.58824 1" />
      </material>
    </visual>
    <collision>
      <origin
        xyz="0 0 0"
        rpy="0 0 0" />
      <geometry>
        <mesh
          filename="package://Run_URDF/meshes/elbow_pitch_r.STL" />
      </geometry>
    </collision>
  </link>
  <joint
    name="elbow_pitch_r"
    type="revolute">
    <origin
      xyz="0 0 -0.3"
      rpy="0 0 0" />
    <parent
      link="shoulder-pitch-r" />
    <child
      link="elbow-pitch-r" />
    <axis
      xyz="0 -1 0" />
    <limit
      lower="0"
      upper="2.09"
      effort="57.2"
      velocity="15.71" />
  </joint>
  <link
    name="shoulder_pitch_l">
    <inertial>
      <origin
        xyz="-4.3591E-19 0 -0.14232"
        rpy="0 0 0" />
      <mass
        value="6.3152" />
      <inertia
        ixx="0.055898"
        ixy="3.3087E-21"
        ixz="-8.1523E-19"
        iyy="0.05583"
        iyz="-9.4966E-19"
        izz="0.0026781" />
    </inertial>
    <visual>
      <origin
        xyz="0 0 0"
        rpy="0 0 0" />
      <geometry>
        <mesh
          filename="package://Run_URDF/meshes/shoulder_pitch_l.STL" />
      </geometry>
      <material
        name="">
        <color
          rgba="0.64706 0.61961 0.58824 1" />
      </material>
    </visual>
    <collision>
      <origin
        xyz="0 0 0"
        rpy="0 0 0" />
      <geometry>
        <mesh
          filename="package://Run_URDF/meshes/shoulder_pitch_l.STL" />
      </geometry>
    </collision>
  </link>
  <joint
    name="shoulder_pitch_l"
    type="revolute">
    <origin
      xyz="0 0.175 0.6"
      rpy="0 0 0" />
    <parent
      link="base_link" />
    <child
      link="shoulder-pitch-l" />
    <axis
      xyz="0 1 0" />
    <limit
      lower="-1.57"
      upper="1.57"
      effort="57.2"
      velocity="15.71" />
  </joint>
  <link
    name="elbow_pitch_l">
    <inertial>
      <origin
        xyz="2.4148E-18 2.7756E-17 -0.16991"
        rpy="0 0 0" />
      <mass
        value="5.3737" />
      <inertia
        ixx="0.054667"
        ixy="-8.2201E-21"
        ixz="-1.3515E-19"
        iyy="0.054709"
        iyz="-3.3942E-20"
        izz="0.0016306" />
    </inertial>
    <visual>
      <origin
        xyz="0 0 0"
        rpy="0 0 0" />
      <geometry>
        <mesh
          filename="package://Run_URDF/meshes/elbow_pitch_l.STL" />
      </geometry>
      <material
        name="">
        <color
          rgba="0.64706 0.61961 0.58824 1" />
      </material>
    </visual>
    <collision>
      <origin
        xyz="0 0 0"
        rpy="0 0 0" />
      <geometry>
        <mesh
          filename="package://Run_URDF/meshes/elbow_pitch_l.STL" />
      </geometry>
    </collision>
  </link>
  <joint
    name="elbow_pitch_l"
    type="revolute">
    <origin
      xyz="0 0 -0.3"
      rpy="0 0 0" />
    <parent
      link="shoulder-pitch-l" />
    <child
      link="elbow-pitch-l" />
    <axis
      xyz="0 -1 0" />
    <limit
      lower="0"
      upper="2.09"
      effort="57.2"
      velocity="15.71" />
  </joint>
  <link
    name="waist_yaw">
    <inertial>
      <origin
        xyz="-1.9224E-18 8.054E-18 -0.0242"
        rpy="0 0 0" />
      <mass
        value="4.4171" />
      <inertia
        ixx="0.017921"
        ixy="-1.3235E-18"
        ixz="-4.5975E-19"
        iyy="0.0031594"
        iyz="9.9197E-19"
        izz="0.018908" />
    </inertial>
    <visual>
      <origin
        xyz="0 0 0"
        rpy="0 0 0" />
      <geometry>
        <mesh
          filename="package://Run_URDF/meshes/waist_yaw.STL" />
      </geometry>
      <material
        name="">
        <color
          rgba="0.64706 0.61961 0.58824 1" />
      </material>
    </visual>
    <collision>
      <origin
        xyz="0 0 0"
        rpy="0 0 0" />
      <geometry>
        <mesh
          filename="package://Run_URDF/meshes/waist_yaw.STL" />
      </geometry>
    </collision>
  </link>
  <joint
    name="waist_yaw"
    type="revolute">
    <origin
      xyz="0 0 0"
      rpy="0 0 0" />
    <parent
      link="base_link" />
    <child
      link="waist-yaw" />
    <axis
      xyz="0 0 1" />
    <limit
      lower="-1.047"
      upper="1.047"
      effort="57.2"
      velocity="15.71" />
  </joint>
  <link
    name="hip_roll_r">
    <inertial>
      <origin
        xyz="-1.4364E-08 6.9943E-08 1.1019E-07"
        rpy="0 0 0" />
      <mass
        value="0.64002" />
      <inertia
        ixx="0.00018046"
        ixy="1.156E-10"
        ixz="9.9858E-11"
        iyy="0.00025371"
        iyz="3.6752E-10"
        izz="0.00023919" />
    </inertial>
    <visual>
      <origin
        xyz="0 0 0"
        rpy="0 0 0" />
      <geometry>
        <mesh
          filename="package://Run_URDF/meshes/hip_roll_r.STL" />
      </geometry>
      <material
        name="">
        <color
          rgba="0.64706 0.61961 0.58824 1" />
      </material>
    </visual>
    <collision>
      <origin
        xyz="0 0 0"
        rpy="0 0 0" />
      <geometry>
        <mesh
          filename="package://Run_URDF/meshes/hip_roll_r.STL" />
      </geometry>
    </collision>
  </link>
  <joint
    name="hip_roll_r"
    type="revolute">
    <origin
      xyz="0 -0.1 -0.025"
      rpy="0 0 0" />
    <parent
      link="waist-yaw" />
    <child
      link="hip-roll-r" />
    <axis
      xyz="-1 0 0" />
    <limit
      lower="0"
      upper="1.047"
      effort="57.2"
      velocity="15.71" />
  </joint>
  <link
    name="hip_yaw_r">
    <inertial>
      <origin
        xyz="4.0405E-18 -1.3878E-17 -0.044957"
        rpy="0 0 0" />
      <mass
        value="0.76389" />
      <inertia
        ixx="0.00057967"
        ixy="-2.8124E-20"
        ixz="-6.8997E-21"
        iyy="0.0005181"
        iyz="6.6174E-21"
        izz="0.00034433" />
    </inertial>
    <visual>
      <origin
        xyz="0 0 0"
        rpy="0 0 0" />
      <geometry>
        <mesh
          filename="package://Run_URDF/meshes/hip_yaw_r.STL" />
      </geometry>
      <material
        name="">
        <color
          rgba="0.64706 0.61961 0.58824 1" />
      </material>
    </visual>
    <collision>
      <origin
        xyz="0 0 0"
        rpy="0 0 0" />
      <geometry>
        <mesh
          filename="package://Run_URDF/meshes/hip_yaw_r.STL" />
      </geometry>
    </collision>
  </link>
  <joint
    name="hip_yaw_r"
    type="revolute">
    <origin
      xyz="0 0 0"
      rpy="0 0 0" />
    <parent
      link="hip-roll-r" />
    <child
      link="hip-yaw-r" />
    <axis
      xyz="0 0 1" />
    <limit
      lower="-1.047"
      upper="1.047"
      effort="57.2"
      velocity="15.71" />
  </joint>
  <link
    name="hip_pitch_r">
    <inertial>
      <origin
        xyz="-6.8557E-07 -1.249E-16 -0.175"
        rpy="0 0 0" />
      <mass
        value="5.5114" />
      <inertia
        ixx="0.060149"
        ixy="4.4854E-20"
        ixz="-5.6114E-19"
        iyy="0.060232"
        iyz="-1.0459E-18"
        izz="0.0016576" />
    </inertial>
    <visual>
      <origin
        xyz="0 0 0"
        rpy="0 0 0" />
      <geometry>
        <mesh
          filename="package://Run_URDF/meshes/hip_pitch_r.STL" />
      </geometry>
      <material
        name="">
        <color
          rgba="0.64706 0.61961 0.58824 1" />
      </material>
    </visual>
    <collision>
      <origin
        xyz="0 0 0"
        rpy="0 0 0" />
      <geometry>
        <mesh
          filename="package://Run_URDF/meshes/hip_pitch_r.STL" />
      </geometry>
    </collision>
  </link>
  <joint
    name="hip_pitch_r"
    type="revolute">
    <origin
      xyz="4.4545E-05 0 -0.06"
      rpy="0 0 0" />
    <parent
      link="hip-yaw-r" />
    <child
      link="hip-pitch-r" />
    <axis
      xyz="0 -1 0" />
    <limit
      lower="-1.57"
      upper="1.57"
      effort="57.2"
      velocity="15.71" />
  </joint>
  <link
    name="knee_pitch_r">
    <inertial>
      <origin
        xyz="-4.4545E-05 -1.3878E-17 -0.17"
        rpy="0 0 0" />
      <mass
        value="5.5417" />
      <inertia
        ixx="0.060812"
        ixy="6.6174E-20"
        ixz="-5.3953E-19"
        iyy="0.060689"
        iyz="-5.7841E-19"
        izz="0.0019416" />
    </inertial>
    <visual>
      <origin
        xyz="0 0 0"
        rpy="0 0 0" />
      <geometry>
        <mesh
          filename="package://Run_URDF/meshes/knee_pitch_r.STL" />
      </geometry>
      <material
        name="">
        <color
          rgba="0.64706 0.61961 0.58824 1" />
      </material>
    </visual>
    <collision>
      <origin
        xyz="0 0 0"
        rpy="0 0 0" />
      <geometry>
        <mesh
          filename="package://Run_URDF/meshes/knee_pitch_r.STL" />
      </geometry>
    </collision>
  </link>
  <joint
    name="knee_pitch_r"
    type="revolute">
    <origin
      xyz="0 0 -0.35"
      rpy="0 0 0" />
    <parent
      link="hip-pitch-r" />
    <child
      link="knee-pitch-r" />
    <axis
      xyz="0 1 0" />
    <limit
      lower="0"
      upper="2.44"
      effort="57.2"
      velocity="15.71" />
  </joint>
  <link
    name="ankle_pitch_r">
    <inertial>
      <origin
        xyz="0.042099 0 -0.042192"
        rpy="0 0 0" />
      <mass
        value="1.9849" />
      <inertia
        ixx="0.001971"
        ixy="-6.8927E-19"
        ixz="0.0012791"
        iyy="0.011236"
        iyz="1.5592E-20"
        izz="0.01119" />
    </inertial>
    <visual>
      <origin
        xyz="0 0 0"
        rpy="0 0 0" />
      <geometry>
        <mesh
          filename="package://Run_URDF/meshes/ankle_pitch_r.STL" />
      </geometry>
      <material
        name="">
        <color
          rgba="0.64706 0.61961 0.58824 1" />
      </material>
    </visual>
    <collision>
      <origin
        xyz="0 0 0"
        rpy="0 0 0" />
      <geometry>
        <mesh
          filename="package://Run_URDF/meshes/ankle_pitch_r.STL" />
      </geometry>
    </collision>
  </link>
  <joint
    name="ankle_pitch_r"
    type="revolute">
    <origin
      xyz="-4.4545E-05 0 -0.34"
      rpy="0 0 0" />
    <parent
      link="knee-pitch-r" />
    <child
      link="ankle-pitch-r" />
    <axis
      xyz="0 1 0" />
    <limit
      lower="-0.52"
      upper="0.52"
      effort="57.2"
      velocity="15.71" />
  </joint>
  <link
    name="hip_roll_l">
    <inertial>
      <origin
        xyz="-1.4364E-08 6.9943E-08 1.1019E-07"
        rpy="0 0 0" />
      <mass
        value="0.64002" />
      <inertia
        ixx="0.00018046"
        ixy="1.156E-10"
        ixz="9.9858E-11"
        iyy="0.00025371"
        iyz="3.6752E-10"
        izz="0.00023919" />
    </inertial>
    <visual>
      <origin
        xyz="0 0 0"
        rpy="0 0 0" />
      <geometry>
        <mesh
          filename="package://Run_URDF/meshes/hip_roll_l.STL" />
      </geometry>
      <material
        name="">
        <color
          rgba="0.64706 0.61961 0.58824 1" />
      </material>
    </visual>
    <collision>
      <origin
        xyz="0 0 0"
        rpy="0 0 0" />
      <geometry>
        <mesh
          filename="package://Run_URDF/meshes/hip_roll_l.STL" />
      </geometry>
    </collision>
  </link>
  <joint
    name="hip_roll_l"
    type="revolute">
    <origin
      xyz="0 0.1 -0.025"
      rpy="0 0 0" />
    <parent
      link="waist-yaw" />
    <child
      link="hip-roll-l" />
    <axis
      xyz="-1 0 0" />
    <limit
      lower="0"
      upper="1.047"
      effort="57.2"
      velocity="15.71" />
  </joint>
  <link
    name="hip_yaw_l">
    <inertial>
      <origin
        xyz="3.8132E-18 -2.7756E-17 -0.044957"
        rpy="0 0 0" />
      <mass
        value="0.76389" />
      <inertia
        ixx="0.00057967"
        ixy="-2.0584E-20"
        ixz="-7.9182E-21"
        iyy="0.0005181"
        iyz="6.6174E-21"
        izz="0.00034433" />
    </inertial>
    <visual>
      <origin
        xyz="0 0 0"
        rpy="0 0 0" />
      <geometry>
        <mesh
          filename="package://Run_URDF/meshes/hip_yaw_l.STL" />
      </geometry>
      <material
        name="">
        <color
          rgba="0.64706 0.61961 0.58824 1" />
      </material>
    </visual>
    <collision>
      <origin
        xyz="0 0 0"
        rpy="0 0 0" />
      <geometry>
        <mesh
          filename="package://Run_URDF/meshes/hip_yaw_l.STL" />
      </geometry>
    </collision>
  </link>
  <joint
    name="hip_yaw_l"
    type="revolute">
    <origin
      xyz="0 0 0"
      rpy="0 0 0" />
    <parent
      link="hip-roll-l" />
    <child
      link="hip-yaw-l" />
    <axis
      xyz="0 0 1" />
    <limit
      lower="-1.047"
      upper="1.047"
      effort="57.2"
      velocity="15.71" />
  </joint>
  <link
    name="hip_pitch_l">
    <inertial>
      <origin
        xyz="-6.8557E-07 -1.249E-16 -0.175"
        rpy="0 0 0" />
      <mass
        value="5.5114" />
      <inertia
        ixx="0.060149"
        ixy="2.6632E-20"
        ixz="-1.2758E-18"
        iyy="0.060232"
        iyz="-2.6475E-18"
        izz="0.0016576" />
    </inertial>
    <visual>
      <origin
        xyz="0 0 0"
        rpy="0 0 0" />
      <geometry>
        <mesh
          filename="package://Run_URDF/meshes/hip_pitch_l.STL" />
      </geometry>
      <material
        name="">
        <color
          rgba="0.64706 0.61961 0.58824 1" />
      </material>
    </visual>
    <collision>
      <origin
        xyz="0 0 0"
        rpy="0 0 0" />
      <geometry>
        <mesh
          filename="package://Run_URDF/meshes/hip_pitch_l.STL" />
      </geometry>
    </collision>
  </link>
  <joint
    name="hip_pitch_l"
    type="revolute">
    <origin
      xyz="4.4545E-05 0 -0.06"
      rpy="0 0 0" />
    <parent
      link="hip-yaw-l" />
    <child
      link="hip-pitch-l" />
    <axis
      xyz="0 -1 0" />
    <limit
      lower="-1.57"
      upper="1.57"
      effort="57.2"
      velocity="15.71" />
  </joint>
  <link
    name="knee_pitch_l">
    <inertial>
      <origin
        xyz="-4.4545E-05 -1.3878E-17 -0.17"
        rpy="0 0 0" />
      <mass
        value="5.5417" />
      <inertia
        ixx="0.060812"
        ixy="7.2792E-20"
        ixz="-4.8659E-19"
        iyy="0.060689"
        iyz="-2.6077E-19"
        izz="0.0019416" />
    </inertial>
    <visual>
      <origin
        xyz="0 0 0"
        rpy="0 0 0" />
      <geometry>
        <mesh
          filename="package://Run_URDF/meshes/knee_pitch_l.STL" />
      </geometry>
      <material
        name="">
        <color
          rgba="0.64706 0.61961 0.58824 1" />
      </material>
    </visual>
    <collision>
      <origin
        xyz="0 0 0"
        rpy="0 0 0" />
      <geometry>
        <mesh
          filename="package://Run_URDF/meshes/knee_pitch_l.STL" />
      </geometry>
    </collision>
  </link>
  <joint
    name="knee_pitch_l"
    type="revolute">
    <origin
      xyz="0 0 -0.35"
      rpy="0 0 0" />
    <parent
      link="hip-pitch-l" />
    <child
      link="knee-pitch-l" />
    <axis
      xyz="0 1 0" />
    <limit
      lower="0"
      upper="2.44"
      effort="57.2"
      velocity="15.71" />
  </joint>
  <link
    name="ankle_pitch_l">
    <inertial>
      <origin
        xyz="0.042099 -1.3878E-17 -0.042192"
        rpy="0 0 0" />
      <mass
        value="1.9849" />
      <inertia
        ixx="0.001971"
        ixy="-4.5778E-19"
        ixz="0.0012791"
        iyy="0.011236"
        iyz="9.4212E-20"
        izz="0.01119" />
    </inertial>
    <visual>
      <origin
        xyz="0 0 0"
        rpy="0 0 0" />
      <geometry>
        <mesh
          filename="package://Run_URDF/meshes/ankle_pitch_l.STL" />
      </geometry>
      <material
        name="">
        <color
          rgba="0.64706 0.61961 0.58824 1" />
      </material>
    </visual>
    <collision>
      <origin
        xyz="0 0 0"
        rpy="0 0 0" />
      <geometry>
        <mesh
          filename="package://Run_URDF/meshes/ankle_pitch_l.STL" />
      </geometry>
    </collision>
  </link>
  <joint
    name="ankle_pitch_l"
    type="revolute">
    <origin
      xyz="-4.4545E-05 0 -0.34"
      rpy="0 0 0" />
    <parent
      link="knee-pitch-l" />
    <child
      link="ankle-pitch-l" />
    <axis
      xyz="0 -1 0" />
    <limit
      lower="-0.52"
      upper="0.52"
      effort="57.2"
      velocity="15.71" />
  </joint>
</robot>
